{"channel":"status","type":"update","data":[{"version":"2.0.10","system":"online","api_version":"v2","connection_id":16061443795302331912,"upcoming_maintenance":[],"emergency":[]}]}
{"method":"subscribe","result":{"channel":"book","depth":10,"snapshot":true,"symbol":"BTC/USD"},"success":true,"time_in":"2026-09-12T15:48:31.839599Z","time_out":"2026-09-12T15:48:31.839634Z"}
{"channel":"book","type":"snapshot","data":[{"symbol":"BTC/USD","bids":[{"price":77362.8,"qty":0.05300065},{"price":77362.7,"qty":0.01292283},{"price":77362.6,"qty":0.64630689},{"price":77360.9,"qty":0.64632088},{"price":77360.7,"qty":0.00023100},{"price":77359.0,"qty":0.00005100},{"price":77357.5,"qty":0.12083041},{"price":77356.7,"qty":0.64635629},{"price":77356.4,"qty":0.96941334},{"price":77356.1,"qty":0.03000000}],"asks":[{"price":77362.9,"qty":0.01931963},{"price":77363.3,"qty":0.64630206},{"price":77364.2,"qty":0.07194861},{"price":77364.9,"qty":0.00012400},{"price":77366.2,"qty":0.76804238},{"price":77366.6,"qty":0.02585305},{"price":77366.9,"qty":0.44670567},{"price":77367.4,"qty":0.03000000},{"price":77370.5,"qty":0.00005100},{"price":77371.3,"qty":0.28936988}],"checksum":851511627,"timestamp":"2026-09-12T15:48:31.964868Z"}]}
{"channel":"book","type":"update","data":[{"symbol":"BTC/USD","bids":[],"asks":[{"price":77366.2,"qty":0.69913991}],"checksum":3561285941,"timestamp":"2026-09-12T15:48:32.340708Z"}]}
{"channel":"book","type":"update","data":[{"symbol":"BTC/USD","bids":[],"asks":[{"price":77366.2,"qty":0.64627737}],"checksum":2802610877,"timestamp":"2026-09-12T15:48:32.341241Z"}]}
{"channel":"book","type":"update","data":[{"symbol":"BTC/USD","bids":[{"price":77360.8,"qty":0.44670567}],"asks":[],"checksum":3766198294,"timestamp":"2026-09-12T15:48:32.364945Z"}]}
{"channel":"book","type":"update","data":[{"symbol":"BTC/USD","bids":[],"asks":[{"price":77362.9,"qty":0.07301963}],"checksum":3844400186,"timestamp":"2026-09-12T15:48:32.600842Z"}]}
{"channel":"book","type":"update","data":[{"symbol":"BTC/USD","bids":[{"price":77362.8,"qty":0.05251592},{"price":77362.8,"qty":0.01093915},{"price":77362.8,"qty":0.00000065}],"asks":[],"checksum":3129346762,"timestamp":"2026-09-12T15:48:32.604001Z"}]}
{"channel":"heartbeat"}
{"channel":"book","type":"update","data":[{"symbol":"BTC/USD","bids":[{"price":77362.8,"qty":0.00048538}],"asks":[],"checksum":2263077260,"timestamp":"2026-09-12T15:48:32.673864Z"}]}
{"channel":"book","type":"update","data":[{"symbol":"BTC/USD","bids":[{"price":77360.9,"qty":0.00000000},{"price":77355.7,"qty":0.05370000}],"asks":[],"checksum":3024560236,"timestamp":"2026-09-12T15:48:33.295917Z"}]}
{"channel":"book","type":"update","data":[{"symbol":"BTC/USD","bids":[{"price":77359.6,"qty":0.64633182}],"asks":[],"checksum":1909694735,"timestamp":"2026-09-12T15:48:33.296703Z"}]}
{"channel":"book","type":"update","data":[{"symbol":"BTC/USD","bids":[{"price":77359.6,"qty":0.00000000},{"price":77355.7,"qty":0.05370000}],"asks":[],"checksum":3024560236,"timestamp":"2026-09-12T15:48:33.299941Z"}]}
{"channel":"heartbeat"}
{"channel":"book","type":"update","data":[{"symbol":"BTC/USD","bids":[{"price":77356.1,"qty":0.03000000}],"asks":[],"checksum":482447018,"timestamp":"2026-09-12T15:48:33.747928Z"}]}
{"channel":"book","type":"update","data":[{"symbol":"BTC/USD","bids":[{"price":77361.0,"qty":0.64632047}],"asks":[],"checksum":1690825246,"timestamp":"2026-09-12T15:48:34.580348Z"}]}
{"channel":"heartbeat"}
{"channel":"heartbeat"}
{"channel":"book","type":"update","data":[{"symbol":"BTC/USD","bids":[],"asks":[{"price":77362.9,"qty":0.07287537},{"price":77362.9,"qty":0.07263946}],"checksum":3774051031,"timestamp":"2026-09-12T15:48:36.167719Z"}]}
{"channel":"book","type":"update","data":[{"symbol":"BTC/USD","bids":[],"asks":[{"price":77362.9,"qty":0.07312419}],"checksum":3155849120,"timestamp":"2026-09-12T15:48:36.195555Z"}]}
{"channel":"heartbeat"}
{"channel":"book","type":"update","data":[{"symbol":"BTC/USD","bids":[{"price":77360.8,"qty":0.00000000},{"price":77356.1,"qty":0.03000000}],"asks":[],"checksum":1974059014,"timestamp":"2026-09-12T15:48:36.929051Z"}]}
{"channel":"book","type":"update","data":[{"symbol":"BTC/USD","bids":[{"price":77361.0,"qty":0.00000000},{"price":77355.7,"qty":0.05370000}],"asks":[],"checksum":38358770,"timestamp":"2026-09-12T15:48:36.932212Z"}]}
{"channel":"book","type":"update","data":[{"symbol":"BTC/USD","bids":[{"price":77362.6,"qty":0.00000000},{"price":77355.2,"qty":0.00005100}],"asks":[],"checksum":3954992311,"timestamp":"2026-09-12T15:48:36.932717Z"}]}
{"channel":"book","type":"update","data":[{"symbol":"BTC/USD","bids":[{"price":77356.7,"qty":0.00000000},{"price":77352.8,"qty":0.00006579}],"asks":[],"checksum":2147276223,"timestamp":"2026-09-12T15:48:36.934664Z"}]}
{"channel":"book","type":"update","data":[{"symbol":"BTC/USD","bids":[],"asks":[{"price":77366.2,"qty":0.00000000},{"price":77371.4,"qty":0.96941334}],"checksum":1362436619,"timestamp":"2026-09-12T15:48:36.935093Z"}]}
{"channel":"book","type":"update","data":[{"symbol":"BTC/USD","bids":[{"price":77356.1,"qty":0.00000000},{"price":77352.0,"qty":0.00692093},{"price":77353.1,"qty":0.03000000}],"asks":[],"checksum":1526507155,"timestamp":"2026-09-12T15:48:36.935265Z"}]}
{"channel":"book","type":"update","data":[{"symbol":"BTC/USD","bids":[],"asks":[{"price":77362.9,"qty":0.10617334}],"checksum":2106032100,"timestamp":"2026-09-12T15:48:36.940231Z"}]}
{"channel":"book","type":"update","data":[{"symbol":"BTC/USD","bids":[{"price":77362.8,"qty":0.00048473}],"asks":[],"checksum":1391011287,"timestamp":"2026-09-12T15:48:36.943727Z"}]}
{"channel":"book","type":"update","data":[{"symbol":"BTC/USD","bids":[],"asks":[{"price":77364.7,"qty":0.64629001}],"checksum":3313313782,"timestamp":"2026-09-12T15:48:36.945040Z"}]}
{"channel":"book","type":"update","data":[{"symbol":"BTC/USD","bids":[{"price":77362.7,"qty":0.00000000},{"price":77352.0,"qty":0.00692093},{"price":77357.6,"qty":0.01351086}],"asks":[],"checksum":3114996782,"timestamp":"2026-09-12T15:48:36.947022Z"}]}
{"channel":"book","type":"update","data":[{"symbol":"BTC/USD","bids":[],"asks":[{"price":77369.6,"qty":0.64624942}],"checksum":755876606,"timestamp":"2026-09-12T15:48:36.947132Z"}]}
{"channel":"book","type":"update","data":[{"symbol":"BTC/USD","bids":[{"price":77360.5,"qty":0.64632411}],"asks":[],"checksum":3475822414,"timestamp":"2026-09-12T15:48:36.948491Z"}]}
{"channel":"book","type":"update","data":[{"symbol":"BTC/USD","bids":[{"price":77359.1,"qty":0.64633564}],"asks":[],"checksum":831677066,"timestamp":"2026-09-12T15:48:36.948743Z"}]}
{"channel":"book","type":"update","data":[{"symbol":"BTC/USD","bids":[],"asks":[{"price":77369.5,"qty":0.48229056}],"checksum":2170011232,"timestamp":"2026-09-12T15:48:36.951212Z"}]}
{"channel":"book","type":"update","data":[{"symbol":"BTC/USD","bids":[],"asks":[{"price":77363.2,"qty":0.55736618}],"checksum":1431868758,"timestamp":"2026-09-12T15:48:36.952110Z"}]}
{"channel":"book","type":"update","data":[{"symbol":"BTC/USD","bids":[],"asks":[{"price":77362.9,"qty":0.09483622}],"checksum":4143602340,"timestamp":"2026-09-12T15:48:36.956170Z"}]}
{"channel":"book","type":"update","data":[{"symbol":"BTC/USD","bids":[{"price":77362.8,"qty":0.01142388}],"asks":[],"checksum":2591066737,"timestamp":"2026-09-12T15:48:36.959139Z"}]}
{"channel":"book","type":"update","data":[{"symbol":"BTC/USD","bids":[],"asks":[{"price":77362.9,"qty":0.06178707}],"checksum":68569454,"timestamp":"2026-09-12T15:48:36.959243Z"}]}
{"channel":"book","type":"update","data":[{"symbol":"BTC/USD","bids":[],"asks":[{"price":77362.9,"qty":0.09483622}],"checksum":2591066737,"timestamp":"2026-09-12T15:48:36.962187Z"}]}
{"channel":"book","type":"update","data":[{"symbol":"BTC/USD","bids":[{"price":77362.8,"qty":0.00048473}],"asks":[],"checksum":4143602340,"timestamp":"2026-09-12T15:48:36.963843Z"}]}
{"channel":"book","type":"update","data":[{"symbol":"BTC/USD","bids":[{"price":77360.5,"qty":0.00000000},{"price":77353.8,"qty":0.64638007}],"asks":[],"checksum":3580273,"timestamp":"2026-09-12T15:48:36.982610Z"}]}
{"channel":"book","type":"update","data":[{"symbol":"BTC/USD","bids":[],"asks":[{"price":77363.2,"qty":0.00000000},{"price":77369.6,"qty":0.64624942}],"checksum":3560540743,"timestamp":"2026-09-12T15:48:37.074711Z"}]}
{"channel":"book","type":"update","data":[{"symbol":"BTC/USD","bids":[{"price":77357.6,"qty":0.00000000},{"price":77352.8,"qty":0.00006579},{"price":77359.2,"qty":0.07189459}],"asks":[],"checksum":2829455341,"timestamp":"2026-09-12T15:48:37.098404Z"}]}
{"channel":"book","type":"update","data":[{"symbol":"BTC/USD","bids":[{"price":77359.1,"qty":0.00000000},{"price":77352.8,"qty":0.00006579}],"asks":[],"checksum":1179249468,"timestamp":"2026-09-12T15:48:37.174223Z"}]}
{"channel":"book","type":"update","data":[{"symbol":"BTC/USD","bids":[{"price":77362.6,"qty":0.64630638}],"asks":[],"checksum":3590664815,"timestamp":"2026-09-12T15:48:37.175031Z"}]}
{"channel":"book","type":"update","data":[{"symbol":"BTC/USD","bids":[{"price":77362.8,"qty":0.00000000},{"price":77352.8,"qty":0.00006579}],"asks":[{"price":77362.7,"qty":0.07795366}],"checksum":2533402272,"timestamp":"2026-09-12T15:48:37.176131Z"}]}
{"channel":"book","type":"update","data":[{"symbol":"BTC/USD","bids":[],"asks":[{"price":77362.7,"qty":0.13165366}],"checksum":2901203453,"timestamp":"2026-09-12T15:48:37.177869Z"}]}
{"channel":"book","type":"update","data":[{"symbol":"BTC/USD","bids":[{"price":77361.3,"qty":0.44670567}],"asks":[],"checksum":3196353679,"timestamp":"2026-09-12T15:48:37.179505Z"}]}
{"channel":"book","type":"update","data":[{"symbol":"BTC/USD","bids":[],"asks":[{"price":77362.7,"qty":0.16470257}],"checksum":1358437587,"timestamp":"2026-09-12T15:48:37.179689Z"}]}
{"channel":"book","type":"update","data":[{"symbol":"BTC/USD","bids":[],"asks":[{"price":77362.9,"qty":0.06178707}],"checksum":1173178893,"timestamp":"2026-09-12T15:48:37.179727Z"}]}
{"channel":"book","type":"update","data":[{"symbol":"BTC/USD","bids":[{"price":77362.6,"qty":0.65724554}],"asks":[],"checksum":1826142268,"timestamp":"2026-09-12T15:48:37.182384Z"}]}
{"channel":"book","type":"update","data":[{"symbol":"BTC/USD","bids":[],"asks":[{"price":77362.7,"qty":0.13165366}],"checksum":2191841376,"timestamp":"2026-09-12T15:48:37.182688Z"}]}
{"channel":"book","type":"update","data":[{"symbol":"BTC/USD","bids":[{"price":77362.6,"qty":0.67394071}],"asks":[],"checksum":3360939875,"timestamp":"2026-09-12T15:48:37.189085Z"}]}
{"channel":"book","type":"update","data":[{"symbol":"BTC/USD","bids":[],"asks":[{"price":77362.7,"qty":0.22648077}],"checksum":354193551,"timestamp":"2026-09-12T15:48:37.189117Z"}]}
{"channel":"book","type":"update","data":[{"symbol":"BTC/USD","bids":[{"price":77362.6,"qty":0.67442544}],"asks":[],"checksum":2804019408,"timestamp":"2026-09-12T15:48:37.207120Z"}]}
{"channel":"book","type":"update","data":[{"symbol":"BTC/USD","bids":[],"asks":[{"price":77367.4,"qty":0.00000000},{"price":77369.6,"qty":0.64624942},{"price":77368.9,"qty":0.03000000}],"checksum":3868266353,"timestamp":"2026-09-12T15:48:37.236782Z"}]}
{"channel":"book","type":"update","data":[{"symbol":"BTC/USD","bids":[{"price":77356.4,"qty":0.00000000},{"price":77352.8,"qty":0.00006579}],"asks":[],"checksum":3685833301,"timestamp":"2026-09-12T15:48:37.242618Z"}]}
{"channel":"book","type":"update","data":[{"symbol":"BTC/USD","bids":[],"asks":[{"price":77369.5,"qty":0.00000000},{"price":77369.6,"qty":0.64624942}],"checksum":4123334326,"timestamp":"2026-09-12T15:48:37.243637Z"}]}
{"channel":"book","type":"update","data":[{"symbol":"BTC/USD","bids":[],"asks":[{"price":77369.5,"qty":0.19292068}],"checksum":985541098,"timestamp":"2026-09-12T15:48:37.244756Z"}]}
{"channel":"book","type":"update","data":[{"symbol":"BTC/USD","bids":[{"price":77355.3,"qty":0.96941334}],"asks":[],"checksum":4022463945,"timestamp":"2026-09-12T15:48:37.251308Z"}]}
{"channel":"book","type":"update","data":[{"symbol":"BTC/USD","bids":[{"price":77356.1,"qty":0.03000000}],"asks":[],"checksum":240008708,"timestamp":"2026-09-12T15:48:37.276732Z"}]}
{"channel":"book","type":"update","data":[{"symbol":"BTC/USD","bids":[{"price":77359.2,"qty":0.00000000},{"price":77353.8,"qty":0.64638007},{"price":77361.4,"qty":0.07493616}],"asks":[],"checksum":966902968,"timestamp":"2026-09-12T15:48:37.277471Z"}]}
{"channel":"book","type":"update","data":[{"symbol":"BTC/USD","bids":[],"asks":[{"price":77362.9,"qty":0.06130234},{"price":77362.7,"qty":0.22696550}],"checksum":2593326107,"timestamp":"2026-09-12T15:48:37.312691Z"}]}
{"channel":"book","type":"update","data":[{"symbol":"BTC/USD","bids":[],"asks":[{"price":77362.9,"qty":0.00760234}],"checksum":961227827,"timestamp":"2026-09-12T15:48:37.329583Z"}]}
{"channel":"book","type":"update","data":[{"symbol":"BTC/USD","bids":[],"asks":[{"price":77362.9,"qty":0.06020893}],"checksum":2522375864,"timestamp":"2026-09-12T15:48:37.417057Z"}]}
{"channel":"book","type":"update","data":[{"symbol":"BTC/USD","bids":[],"asks":[{"price":77368.9,"qty":0.00000000},{"price":77369.6,"qty":0.64624942},{"price":77368.4,"qty":0.03000000}],"checksum":3569598041,"timestamp":"2026-09-12T15:48:37.417192Z"}]}
{"channel":"book","type":"update","data":[{"symbol":"BTC/USD","bids":[],"asks":[{"price":77365.6,"qty":0.06784225}],"checksum":2518223274,"timestamp":"2026-09-12T15:48:37.418517Z"}]}
{"channel":"book","type":"update","data":[{"symbol":"BTC/USD","bids":[],"asks":[{"price":77362.8,"qty":0.00005100}],"checksum":769401238,"timestamp":"2026-09-12T15:48:37.491177Z"}]}
{"channel":"book","type":"update","data":[{"symbol":"BTC/USD","bids":[{"price":77360.8,"qty":0.64632150}],"asks":[],"checksum":4141672417,"timestamp":"2026-09-12T15:48:37.580714Z"}]}
{"channel":"heartbeat"}
{"channel":"book","type":"update","data":[{"symbol":"BTC/USD","bids":[{"price":77362.6,"qty":0.65773027}],"asks":[],"checksum":3336391897,"timestamp":"2026-09-12T15:48:37.689530Z"}]}
{"channel":"book","type":"update","data":[{"symbol":"BTC/USD","bids":[],"asks":[{"price":77362.9,"qty":0.06010893}],"checksum":4242247869,"timestamp":"2026-09-12T15:48:37.886044Z"}]}
{"channel":"book","type":"update","data":[{"symbol":"BTC/USD","bids":[],"asks":[{"price":77362.9,"qty":0.05934484}],"checksum":3956378414,"timestamp":"2026-09-12T15:48:38.016585Z"}]}
{"channel":"book","type":"update","data":[{"symbol":"BTC/USD","bids":[],"asks":[{"price":77366.6,"qty":0.02590405}],"checksum":3741943346,"timestamp":"2026-09-12T15:48:38.036362Z"}]}
{"channel":"book","type":"update","data":[{"symbol":"BTC/USD","bids":[],"asks":[{"price":77362.7,"qty":0.22683752}],"checksum":2946476070,"timestamp":"2026-09-12T15:48:38.148158Z"}]}
{"channel":"book","type":"update","data":[{"symbol":"BTC/USD","bids":[{"price":77355.3,"qty":0.00000000},{"price":77355.2,"qty":0.00005100}],"asks":[],"checksum":3303310139,"timestamp":"2026-09-12T15:48:38.242849Z"}]}
{"channel":"book","type":"update","data":[{"symbol":"BTC/USD","bids":[{"price":77356.6,"qty":0.96941334}],"asks":[],"checksum":357378,"timestamp":"2026-09-12T15:48:38.272215Z"}]}
{"channel":"heartbeat"}
{"channel":"book","type":"update","data":[{"symbol":"BTC/USD","bids":[{"price":77360.7,"qty":0.00000000},{"price":77355.2,"qty":0.00005100}],"asks":[],"checksum":1061954055,"timestamp":"2026-09-12T15:48:38.661026Z"}]}
{"channel":"book","type":"update","data":[{"symbol":"BTC/USD","bids":[],"asks":[{"price":77362.7,"qty":0.13201041}],"checksum":4105580797,"timestamp":"2026-09-12T15:48:38.740331Z"}]}
{"channel":"book","type":"update","data":[{"symbol":"BTC/USD","bids":[],"asks":[{"price":77364.7,"qty":0.00000000},{"price":77368.4,"qty":0.03000000}],"checksum":3563664909,"timestamp":"2026-09-12T15:48:38.759229Z"}]}
{"channel":"book","type":"update","data":[{"symbol":"BTC/USD","bids":[],"asks":[{"price":77366.1,"qty":0.64627850}],"checksum":382624399,"timestamp":"2026-09-12T15:48:38.759982Z"}]}
{"channel":"book","type":"update","data":[{"symbol":"BTC/USD","bids":[{"price":77360.8,"qty":0.64655250}],"asks":[],"checksum":1897060479,"timestamp":"2026-09-12T15:48:38.868939Z"}]}
{"channel":"book","type":"update","data":[{"symbol":"BTC/USD","bids":[],"asks":[{"price":77362.7,"qty":0.13211041}],"checksum":1459209671,"timestamp":"2026-09-12T15:48:38.895956Z"}]}
{"channel":"book","type":"update","data":[{"symbol":"BTC/USD","bids":[],"asks":[{"price":77362.7,"qty":0.13311041}],"checksum":2472809828,"timestamp":"2026-09-12T15:48:39.037084Z"}]}
{"channel":"heartbeat"}
{"channel":"book","type":"update","data":[{"symbol":"BTC/USD","bids":[],"asks":[{"price":77366.9,"qty":0.00000000},{"price":77368.4,"qty":0.03000000}],"checksum":1907330995,"timestamp":"2026-09-12T15:48:40.407630Z"}]}
